<?xml version="1.0" ?>
<!-- =================================================================================== -->
<!-- |    This document was autogenerated by xacro from my_robot.urdf.xacro            | -->
<!-- |    EDITING THIS FILE BY HAND IS NOT RECOMMENDED                                 | -->
<!-- =================================================================================== -->
<robot name="my_robot">
  <!-- Robot Base -->
  <link name="base_link">
    <visual>
      <geometry>
        <box size="0.42 0.31 0.18"/>
      </geometry>
      <material name="Cyan">
        <color rgba="0 1.0 1.0 1.0"/>
      </material>
    </visual>
    <collision>
      <geometry>
        <box size="0.42 0.31 0.18"/>
      </geometry>
    </collision>
    <inertial>
      <origin rpy="1.5707963267948966 0 1.5707963267948966" xyz="0 0 0"/>
      <mass value="15"/>
      <inertia ixx="0.261" ixy="0.0" ixz="0.0" iyy="0.34062499999999996" iyz="0.0" izz="0.16062500000000002"/>
    </inertial>
  </link>
  <!-- Robot Footprint -->
  <link name="base_footprint"/>
  <joint name="base_joint" type="fixed">
    <parent link="base_link"/>
    <child link="base_footprint"/>
    <origin rpy="0 0 0" xyz="0.0 0.0 -0.15000000000000002"/>
  </joint>
  <link name="drivewhl_l_link">
    <visual>
      <origin rpy="1.5707963267948966 0 0" xyz="0 0 0"/>
      <geometry>
        <cylinder length="0.04" radius="0.1"/>
      </geometry>
      <material name="Gray">
        <color rgba="0.5 0.5 0.5 1.0"/>
      </material>
    </visual>
    <collision>
      <origin rpy="1.5707963267948966 0 0" xyz="0 0 0"/>
      <geometry>
        <cylinder length="0.04" radius="0.1"/>
      </geometry>
      <surface>
        <friction>
          <ode>
            <mu1>1.2</mu1>
            <mu2>1.2</mu2>
          </ode>
        </friction>
        <contact>
          <ode>
            <kp>500000.0</kp>
            <kd>10.0</kd>
            <max_vel>0.1</max_vel>
            <min_depth>0.001</min_depth>
          </ode>
        </contact>
      </surface>
    </collision>
    <inertial>
      <origin rpy="1.5707963267948966 0 0" xyz="0 0 0"/>
      <mass value="0.5"/>
      <inertia ixx="0.0013166666666666667" ixy="0" ixz="0" iyy="0.0013166666666666667" iyz="0" izz="0.0025000000000000005"/>
    </inertial>
  </link>
  <joint name="drivewhl_l_joint" type="continuous">
    <parent link="base_link"/>
    <child link="drivewhl_l_link"/>
    <origin rpy="0 0 0" xyz="-0.12 0.18 -0.05"/>
    <axis xyz="0 1 0"/>
  </joint>
  <link name="drivewhl_r_link">
    <visual>
      <origin rpy="1.5707963267948966 0 0" xyz="0 0 0"/>
      <geometry>
        <cylinder length="0.04" radius="0.1"/>
      </geometry>
      <material name="Gray">
        <color rgba="0.5 0.5 0.5 1.0"/>
      </material>
    </visual>
    <collision>
      <origin rpy="1.5707963267948966 0 0" xyz="0 0 0"/>
      <geometry>
        <cylinder length="0.04" radius="0.1"/>
      </geometry>
      <surface>
        <friction>
          <ode>
            <mu1>1.2</mu1>
            <mu2>1.2</mu2>
          </ode>
        </friction>
        <contact>
          <ode>
            <kp>500000.0</kp>
            <kd>10.0</kd>
            <max_vel>0.1</max_vel>
            <min_depth>0.001</min_depth>
          </ode>
        </contact>
      </surface>
    </collision>
    <inertial>
      <origin rpy="1.5707963267948966 0 0" xyz="0 0 0"/>
      <mass value="0.5"/>
      <inertia ixx="0.0013166666666666667" ixy="0" ixz="0" iyy="0.0013166666666666667" iyz="0" izz="0.0025000000000000005"/>
    </inertial>
  </link>
  <joint name="drivewhl_r_joint" type="continuous">
    <parent link="base_link"/>
    <child link="drivewhl_r_link"/>
    <origin rpy="0 0 0" xyz="-0.12 -0.18 -0.05"/>
    <axis xyz="0 1 0"/>
  </joint>
  <!-- Caster Wheel -->
  <link name="front_caster">
    <visual>
      <geometry>
        <sphere radius="0.060000000000000026"/>
      </geometry>
      <material name="Cyan">
        <color rgba="0 1.0 1.0 1.0"/>
      </material>
    </visual>
    <collision>
      <origin rpy="0 0 0" xyz="0 0 0"/>
      <geometry>
        <sphere radius="0.060000000000000026"/>
      </geometry>
    </collision>
    <inertial>
      <mass value="0.5"/>
      <inertia ixx="0.0007200000000000006" ixy="0.0" ixz="0.0" iyy="0.0007200000000000006" iyz="0.0" izz="0.0007200000000000006"/>
    </inertial>
  </link>
  <!-- Adding slippery mate5rial -->
  <gazebo reference="front_caster">
    <mu1>0.01</mu1>
    <mu2>0.01</mu2>
    <visual>
      <material>Gazebo/White</material>
    </visual>
  </gazebo>
  <joint name="caster_joint" type="fixed">
    <parent link="base_link"/>
    <child link="front_caster"/>
    <origin rpy="0 0 0" xyz="0.14 0.0 -0.09"/>
  </joint>
  <!-- LIDAR -->
  <joint name="lidar_joint" type="fixed">
    <parent link="base_link"/>
    <child link="lidar_link"/>
    <origin rpy="0 0 0" xyz="0.21 0 0.115"/>
  </joint>
  <link name="lidar_link">
    <visual>
      <origin rpy="0 0 0" xyz="0 0 0"/>
      <geometry>
        <cylinder length="0.05" radius="0.0508"/>
      </geometry>
      <material name="Black">
        <color rgba="0.0 0.0 0.0 1.0"/>
      </material>
    </visual>
    <collision>
      <origin rpy="0 0 0" xyz="0 0 0"/>
      <geometry>
        <cylinder length="0.05" radius="0.0508"/>
      </geometry>
    </collision>
    <inertial>
      <mass value="0.114"/>
      <origin rpy="0 0 0" xyz="0 0 0"/>
      <inertia ixx="0.001" ixy="0" ixz="0" iyy="0.001" iyz="0" izz="0.001"/>
    </inertial>
  </link>
  <joint name="camera_joint" type="fixed">
    <axis xyz="0 1 0"/>
    <origin rpy="0 0 0" xyz="0.21 0 0.18"/>
    <parent link="base_link"/>
    <child link="camera_link"/>
  </joint>
  <!-- Camera -->
  <link name="camera_link">
    <collision>
      <origin rpy="0 0 0" xyz="0 0 0"/>
      <geometry>
        <box size="0.05 0.05 0.05"/>
      </geometry>
    </collision>
    <visual>
      <origin rpy="0 0 0" xyz="0 0 0"/>
      <geometry>
        <box size="0.05 0.05 0.05"/>
      </geometry>
      <material name="red"/>
    </visual>
    <inertial>
      <mass value="1e-5"/>
      <origin rpy="0 0 0" xyz="0 0 0"/>
      <inertia ixx="1e-6" ixy="0" ixz="0" iyy="1e-6" iyz="0" izz="1e-6"/>
    </inertial>
  </link>
  <!-- camera -->
  <gazebo reference="camera_link">
    <sensor name="camera1" type="camera">
      <update_rate>30.0</update_rate>
      <camera name="head">
        <horizontal_fov>1.3962634</horizontal_fov>
        <image>
          <width>1200</width>
          <height>800</height>
          <format>R8G8B8</format>
        </image>
        <clip>
          <near>0.02</near>
          <far>300</far>
        </clip>
        <noise>
          <type>gaussian</type>
          <mean>0.0</mean>
          <stddev>0.007</stddev>
        </noise>
      </camera>
      <plugin filename="libgazebo_ros_camera.so" name="camera_controller">
        <always_on>true</always_on>
        <update_rate>5.0</update_rate>
        <camera_name>camera1</camera_name>
        <ros>
          <namespace>/camera</namespace>
          <remapping>~/out:=image_raw</remapping>
          <remapping>~/out:=camera_info</remapping>
        </ros>
        <output_type>sensor_msgs/CameraInfo</output_type>
        <output_type>sensor_msgs/ImageRaw</output_type>
        <frame_name>camera_link</frame_name>
        <hack_baseline>0.07</hack_baseline>
        <distortion_k1>0.0</distortion_k1>
        <distortion_k2>0.0</distortion_k2>
        <distortion_k3>0.0</distortion_k3>
        <distortion_p1>0.0</distortion_p1>
        <distortion_p2>0.0</distortion_p2>
      </plugin>
      <visualize>true</visualize>
    </sensor>
  </gazebo>
  <gazebo>
    <!-- Differential drive -->
    <plugin filename="libgazebo_ros_diff_drive.so" name="diff_drive">
      <!-- wheels -->
      <left_joint>drivewhl_l_joint</left_joint>
      <right_joint>drivewhl_r_joint</right_joint>
      <!-- kinematics -->
      <wheel_separation>0.35</wheel_separation>
      <wheel_diameter>0.2</wheel_diameter>
      <!-- limits -->
      <max_wheel_torque>20</max_wheel_torque>
      <max_wheel_acceleration>1.0</max_wheel_acceleration>
      <!-- output -->
      <publish_odom>true</publish_odom>
      <publish_odom_tf>true</publish_odom_tf>
      <publish_wheel_tf>true</publish_wheel_tf>
      <odometry_frame>odom_demo</odometry_frame>
      <robot_base_frame>base_link</robot_base_frame>
    </plugin>
  </gazebo>
  <gazebo reference="lidar_link">
    <sensor name="sensor_ray" type="ray">
      <ray>
        <scan>
          <horizontal>
            <samples>360</samples>
            <resolution>1.0</resolution>
            <min_angle>-3.14</min_angle>
            <max_angle>3.14</max_angle>
          </horizontal>
        </scan>
        <range>
          <min>0.5</min>
          <max>50.0</max>
        </range>
      </ray>
      <always_on>true</always_on>
      <update_rate>1.0</update_rate>
      <plugin filename="libgazebo_ros_ray_sensor.so" name="pc2">
        <ros>
          <namespace>/ray</namespace>
          <remapping>~/out:=pointcloud2</remapping>
        </ros>
        <output_type>sensor_msgs/PointCloud2</output_type>
        <frame_name>lidar_link</frame_name>
      </plugin>
      <plugin filename="libgazebo_ros_ray_sensor.so" name="pc">
        <ros>
          <namespace>/ray</namespace>
          <remapping>~/out:=pointcloud</remapping>
        </ros>
        <output_type>sensor_msgs/PointCloud</output_type>
        <frame_name>lidar_link</frame_name>
      </plugin>
      <plugin filename="libgazebo_ros_ray_sensor.so" name="laserscan">
        <ros>
          <namespace>/ray</namespace>
          <remapping>~/out:=laserscan</remapping>
        </ros>
        <output_type>sensor_msgs/LaserScan</output_type>
        <frame_name>lidar_link</frame_name>
      </plugin>
      <plugin filename="libgazebo_ros_ray_sensor.so" name="range">
        <ros>
          <namespace>/ray</namespace>
          <remapping>~/out:=range</remapping>
        </ros>
        <output_type>sensor_msgs/Range</output_type>
        <frame_name>lidar_link</frame_name>
      </plugin>
      <visualize>true</visualize>
    </sensor>
  </gazebo>
</robot>
